Workbook

Sheet Dashboard
B1: ☕ BrewBean Inventory Dashboard
B2: 500 outlet–product stock lines · 10 outlets · 50 products · all figures are live formulas
B4: 🛒 TOTAL UNITS SOLD | E4: 🗑️ TOTAL WASTAGE | H4: 📦 TOTAL CLOSING STOCK | L4: 🎯 AVG STOCK UTILIZATION | O4: 🔔 PRODUCTS REQUIRING REORDER
B5: =SUM(Inventory_Clean!$I$2:$I$501) | E5: =SUM(Inventory_Clean!$J$2:$J$501) | H5: =SUM(Inventory_Clean!$Q$2:$Q$501) | L5: =AVERAGE(Inventory_Clean!$T$2:$T$501) | O5: =COUNTIF(Pivot_Tables!$L$42:$L$91,">0")
B7: ="≈ "&TEXT(B5/10,"#,##0")&" per outlet" | E7: =TEXT(E5/SUM(Inventory_Clean!$O$2:$O$501),"0.00%")&" of stock available" | H7: ="Shortfall on "&COUNTIF(Inventory_Clean!$P$2:$P$501,"<0")&" lines: "&TEXT(SUM(Inventory_Clean!$R$2:$R$501),"#,##0")&" units" | L7: =COUNTIF(Inventory_Clean!$T$2:$T$501,">1")&" lines sold above 100% of stock" | O7: =COUNTIF(Inventory_Clean!$U$2:$U$501,"Reorder Required")&" lines ("&TEXT(COUNTIF(Inventory_Clean!$U$2:$U$501,"Reorder Required")/COUNTA(Inventory_Clean!$A$2:$A$501),"0%")&") at/below reorder level"
B57: 💡 BUSINESS INSIGHTS
B58: Highest-selling outlet | E58: =INDEX(Pivot_Tables!$B$7:$B$16,MATCH(MAX(Pivot_Tables!$C$7:$C$16),Pivot_Tables!$C$7:$C$16,0))&" sold the most – "&TEXT(MAX(Pivot_Tables!$C$7:$C$16),"#,##0")&" units ("&TEXT(MAX(Pivot_Tables!$C$7:$C$16)/Pivot_Tables!$C$17,"0.0%")&" of all units). Lowest: "&INDEX(Pivot_Tables!$B$7:$B$16,MATCH(MIN(Pivot_Tables!$C$7:$C$16),Pivot_Tables!$C$7:$C$16,0))&" with "&TEXT(MIN(Pivot_Tables!$C$7:$C$16),"#,##0")&" units."
B59: Highest-wastage outlet | E59: =INDEX(Pivot_Tables!$F$7:$F$16,MATCH(MAX(Pivot_Tables!$G$7:$G$16),Pivot_Tables!$G$7:$G$16,0))&" has the highest wastage – "&TEXT(MAX(Pivot_Tables!$G$7:$G$16),"#,##0")&" units ("&TEXT(INDEX(Pivot_Tables!$H$7:$H$16,MATCH(MAX(Pivot_Tables!$G$7:$G$16),Pivot_Tables!$G$7:$G$16,0)),"0.00%")&" of available stock). Lowest: "&INDEX(Pivot_Tables!$F$7:$F$16,MATCH(MIN(Pivot_Tables!$G$7:$G$16),Pivot_Tables!$G$7:$G$16,0))&" ("&TEXT(MIN(Pivot_Tables!$G$7:$G$16),"#,##0")&" units)."
B60: Best-selling products | E60: ="Top 3 by units sold: "&INDEX(Pivot_Tables!$R$42:$R$51,1)&" ("&TEXT(INDEX(Pivot_Tables!$S$42:$S$51,1),"#,##0")&" units)"&", "&INDEX(Pivot_Tables!$R$42:$R$51,2)&" ("&TEXT(INDEX(Pivot_Tables!$S$42:$S$51,2),"#,##0")&" units)"&" and "&INDEX(Pivot_Tables!$R$42:$R$51,3)&" ("&TEXT(INDEX(Pivot_Tables!$S$42:$S$51,3),"#,##0")&" units)"&"."
B61: Products requiring reorder | E61: =COUNTIF(Pivot_Tables!$L$42:$L$91,">0")&" of "&COUNTA(Pivot_Tables!$K$42:$K$91)&" products are at/below reorder level in at least one outlet ("&COUNTIF(Inventory_Clean!$U$2:$U$501,"Reorder Required")&" of "&COUNTA(Inventory_Clean!$A$2:$A$501)&" lines). Most exposed products (outlets at/below reorder level): "&INDEX(Pivot_Tables!$K$42:$K$91,MATCH(LARGE(Pivot_Tables!$O$42:$O$91,1),Pivot_Tables!$O$42:$O$91,0))&" ("&TEXT(INDEX(Pivot_Tables!$L$42:$L$91,MATCH(LARGE(Pivot_Tables!$O$42:$O$91,1),Pivot_Tables!$O$42:$O$91,0)),"0")&")"&", "&INDEX(Pivot_Tables!$K$42:$K$91,MATCH(LARGE(Pivot_Tables!$O$42:$O$91,2),Pivot_Tables!$O$42:$O$91,0))&" ("&TEXT(INDEX(Pivot_Tables!$L$42:$L$91,MATCH(LARGE(Pivot_Tables!$O$42:$O$91,2),Pivot_Tables!$O$42:$O$91,0)),"0")&")"&", "&INDEX(Pivot_Tables!$K$42:$K$91,MATCH(LARGE(Pivot_Tables!$O$42:$O$91,3),Pivot_Tables!$O$42:$O$91,0))&" ("&TEXT(INDEX(Pivot_Tables!$L$42:$L$91,MATCH(LARGE(Pivot_Tables!$O$42:$O$91,3),Pivot_Tables!$O$42:$O$91,0)),"0")&")"&". Outlet with most reorder lines: "&INDEX(Pivot_Tables!$J$7:$J$16,MATCH(MAX(Pivot_Tables!$M$7:$M$16),Pivot_Tables!$M$7:$M$16,0))&" ("&MAX(Pivot_Tables!$M$7:$M$16)&")."
B62: Outlets with low stock utilization | E62: ="Below the "&TEXT(Pivot_Tables!$P$17,"0.0%")&" average: "&IF(Pivot_Tables!$V$16="","none",Pivot_Tables!$V$16)&". Lowest: "&INDEX(Pivot_Tables!$O$7:$O$16,MATCH(MIN(Pivot_Tables!$P$7:$P$16),Pivot_Tables!$P$7:$P$16,0))&" ("&TEXT(MIN(Pivot_Tables!$P$7:$P$16),"0.0%")&")."
B63: Products with high wastage | E63: ="Highest wastage: "&INDEX(Pivot_Tables!$G$42:$G$91,MATCH(LARGE(Pivot_Tables!$J$42:$J$91,1),Pivot_Tables!$J$42:$J$91,0))&" ("&TEXT(INDEX(Pivot_Tables!$H$42:$H$91,MATCH(LARGE(Pivot_Tables!$J$42:$J$91,1),Pivot_Tables!$J$42:$J$91,0)),"#,##0")&")"&", "&INDEX(Pivot_Tables!$G$42:$G$91,MATCH(LARGE(Pivot_Tables!$J$42:$J$91,2),Pivot_Tables!$J$42:$J$91,0))&" ("&TEXT(INDEX(Pivot_Tables!$H$42:$H$91,MATCH(LARGE(Pivot_Tables!$J$42:$J$91,2),Pivot_Tables!$J$42:$J$91,0)),"#,##0")&")"&", "&INDEX(Pivot_Tables!$G$42:$G$91,MATCH(LARGE(Pivot_Tables!$J$42:$J$91,3),Pivot_Tables!$J$42:$J$91,0))&" ("&TEXT(INDEX(Pivot_Tables!$H$42:$H$91,MATCH(LARGE(Pivot_Tables!$J$42:$J$91,3),Pivot_Tables!$J$42:$J$91,0)),"#,##0")&")"&" units. Overall wastage is "&TEXT(Pivot_Tables!$I$92,"0.00%")&" of available stock – low, so reorder timing matters more than spoilage."
B64: Data alert | E64: =COUNTIF(Inventory_Clean!$P$2:$P$501,"<0")&" lines end with negative calculated closing stock (units sold exceeded Opening + Received on "&COUNTIF(Inventory_Clean!$T$2:$T$501,">1")&" of them), a combined shortfall of "&TEXT(SUM(Inventory_Clean!$R$2:$R$501),"#,##0")&" units. This points to unrecorded stock receipts or under-stocking – verify with the outlets. Largest shortfall: "&INDEX(Pivot_Tables!$J$7:$J$16,MATCH(MAX(Pivot_Tables!$L$7:$L$16),Pivot_Tables!$L$7:$L$16,0))&" ("&TEXT(MAX(Pivot_Tables!$L$7:$L$16),"#,##0")&" units). No date field exists, so true monthly movement could not be built."
B66: Closing Stock = Opening + Received − Units Sold − Wastage (negatives floored at 0 for totals). Utilization = Units Sold ÷ (Opening + Received). Reorder when Closing Stock ≤ Reorder Level.

Sheet PT_Units_Outlet
A1: Units Sold by Outlet
A3: Row Labels | B3: Sum of Units_Sold
A4: BrewBean RS Puram | B4: 5554
A5: BrewBean Saravanampatti | B5: 4676
A6: BrewBean Saibaba Colony | B6: 4557
A7: BrewBean Gandhipuram | B7: 4419
A8: BrewBean Trichy | B8: 4330
A9: BrewBean Madurai | B9: 4293
A10: BrewBean Tiruppur | B10: 4270
A11: BrewBean Peelamedu | B11: 4251
A12: BrewBean Salem | B12: 4194
A13: BrewBean Pollachi | B13: 4028
A14: Grand Total | B14: 44572

Sheet PT_Units_Product
A1: Units Sold by Product (Category ▸ Product)
A3: Row Labels | B3: Sum of Units_Sold
A4: Coffee | B4: 3809
A5: Product 16 | B5: 1096
A6: Product 1 | B6: 1021
A7: Product 31 | B7: 852
A8: Product 46 | B8: 840
A9: Tea | B9: 3674
A10: Product 49 | B10: 992
A11: Product 34 | B11: 917
A12: Product 4 | B12: 887
A13: Product 19 | B13: 878
A14: Fresh Juice | B14: 3641
A15: Product 20 | B15: 1069
... A69: Grand Total | B69: 44572

Sheet PT_Wastage_Outlet
A1: Wastage by Outlet
A3: Row Labels | B3: Sum of Wastage
A4: BrewBean Trichy | B4: 124
A5: BrewBean Peelamedu | B5: 121
A6: BrewBean Salem | B6: 120
A7: BrewBean Madurai | B7: 117
A8: BrewBean Gandhipuram | B8: 115
A9: BrewBean Tiruppur | B9: 113
A10: BrewBean RS Puram | B10: 112
A11: BrewBean Saibaba Colony | B11: 112
A12: BrewBean Saravanampatti | B12: 109
A13: BrewBean Pollachi | B13: 106
A14: Grand Total | B14: 1149

Sheet PT_Wastage_Product
A1: Wastage by Product (Category ▸ Product)
A3: Row Labels | B3: Sum of Wastage
A4: Coffee | B4: 106
A5: Product 31 | B5: 59
A6: Product 46 | B6: 17
A7: Product 1 | B7: 15
A8: Product 16 | B8: 15
A9: Frappes | B9: 104
A10: Product 33 | B10: 58
A11: Product 3 | B11: 17
A12: Product 18 | B12: 16
A13: Product 48 | B13: 13
A14: Tea | B14: 95
A15: Product 34 | B15: 51
... A69: Grand Total | B69: 1149

Sheet PT_Closing_Outlet
A1: Closing Stock by Outlet (negatives floored at 0)
A3: Row Labels | B3: Sum of Closing_Stock_Adj
A4: BrewBean Pollachi | B4: 3841
A5: BrewBean Tiruppur | B5: 3827
A6: BrewBean Peelamedu | B6: 3676
A7: BrewBean Salem | B7: 3554
A8: BrewBean Gandhipuram | B8: 3335
A9: BrewBean Trichy | B9: 3313
A10: BrewBean Saibaba Colony | B10: 3221
A11: BrewBean Madurai | B11: 3201
A12: BrewBean Saravanampatti | B12: 2984
A13: BrewBean RS Puram | B13: 2131
A14: Grand Total | B14: 33083

Sheet PT_Reorder_Product
A1: Reorder Status by Product
A3: Count of Inventory_ID | B3: Column Labels
A4: Row Labels | B4: Reorder Required | C4: Stock Sufficient | D4: Grand Total
A5: Product 42 | B5: 6 | C5: 4 | D5: 10
A6: Product 44 | B6: 6 | C6: 4 | D6: 10
A7: Product 1 | B7: 5 | C7: 5 | D7: 10
A8: Product 20 | B8: 5 | C8: 5 | D8: 10
A9: Product 16 | B9: 4 | C9: 6 | D9: 10
A10: Product 23 | B10: 4 | C10: 6 | D10: 10
A11: Product 26 | B11: 4 | C11: 6 | D11: 10
A12: Product 40 | B12: 4 | C12: 6 | D12: 10
A13: Product 43 | B13: 4 | C13: 6 | D13: 10
A14: Product 49 | B14: 4 | C14: 6 | D14: 10
A15: Product 9 | B15: 4 | C15: 6 | D15: 10
A16: Product 10 | B16: 3 | C16: 7 | D16: 10
... A53: Product 6 | B53: 1 | C53: 9 | D53: 10
A54: Product 7 | C54: 10 | D54: 10
A55: Grand Total | B55: 132 | C55: 368 | D55: 500

Sheet PT_Util_Outlet
A1: Stock Utilization by Outlet (average)
A3: Row Labels | B3: Average of Stock_Utilization_%
A4: BrewBean RS Puram | B4: 0.88622487
A5: BrewBean Saravanampatti | B5: 0.66922749
A6: BrewBean Saibaba Colony | B6: 0.65399514
A7: BrewBean Trichy | B7: 0.63686087
A8: BrewBean Madurai | B8: 0.61014775
A9: BrewBean Gandhipuram | B9: 0.60321679
A10: BrewBean Peelamedu | B10: 0.57971249
A11: BrewBean Tiruppur | B11: 0.57274582
A12: BrewBean Salem | B12: 0.57257037
A13: BrewBean Pollachi | B13: 0.53579447
A14: Grand Total | B14: 0.63204961

Sheet PT_LeadTime
A1: Supplier Lead Time by Outlet (avg days) – no supplier field in data
A3: Row Labels | B3: Average of Supplier_Lead_Time_Days
A4: BrewBean RS Puram | B4: 3.32
A5: BrewBean Saravanampatti | B5: 3.16
A6: BrewBean Salem | B6: 3.12
A7: BrewBean Madurai | B7: 3.06
A8: BrewBean Peelamedu | B8: 3.04
A9: BrewBean Gandhipuram | B9: 3.02
A10: BrewBean Pollachi | B10: 3
A11: BrewBean Tiruppur | B11: 2.94
A12: BrewBean Saibaba Colony | B12: 2.88
A13: BrewBean Trichy | B13: 2.86
A14: Grand Total | B14: 3.04

Sheet PT_Movement
A1: Inventory Movement by Outlet (no date field in data)
A3: Row Labels | B3: Sum of Opening_Stock | C3: Sum of Received_Stock | D3: Sum of Units_Sold | E3: Sum of Wastage | F3: Sum of Closing_Stock_Adj
A4: BrewBean RS Puram | B4: 4419 | C4: 2779 | D4: 5554 | E4: 112 | F4: 2131
A5: BrewBean Saravanampatti | B5: 4625 | C5: 2994 | D5: 4676 | E5: 109 | F5: 2984
A6: BrewBean Saibaba Colony | B6: 4741 | C6: 2927 | D6: 4557 | E6: 112 | F6: 3221
A7: BrewBean Gandhipuram | B7: 5033 | C7: 2733 | D7: 4419 | E7: 115 | F7: 3335
A8: BrewBean Trichy | B8: 4689 | C8: 2867 | D8: 4330 | E8: 124 | F8: 3313
A9: BrewBean Madurai | B9: 4601 | C9: 2910 | D9: 4293 | E9: 117 | F9: 3201
A10: BrewBean Tiruppur | B10: 5149 | C10: 2957 | D10: 4270 | E10: 113 | F10: 3827
A11: BrewBean Peelamedu | B11: 4875 | C11: 3127 | D11: 4251 | E11: 121 | F11: 3676
A12: BrewBean Salem | B12: 4777 | C12: 3021 | D12: 4194 | E12: 120 | F12: 3554
A13: BrewBean Pollachi | B13: 4708 | C13: 3181 | D13: 4028 | E13: 106 | F13: 3841
A14: Grand Total | B14: 47617 | C14: 29496 | D14: 44572 | E14: 1149 | F14: 33083

Sheet Pivot_Tables
B1: 📊 Dashboard data tables (formula-driven – these feed the dashboard charts)
B2: Each block is a separate pivot-style table. Stock Utilization by Outlet is an average of line-level utilization. Totals row = overall.
B5: 1 · Units Sold by Outlet | F5: 3 · Wastage by Outlet | J5: 5 · Closing Stock by Outlet | O5: 7 · Stock Utilization by Outlet
B6: Outlet | C6: Units Sold | D6: Share of Total | F6: Outlet | G6: Wastage (units) | H6: Wastage % | J6: Outlet | K6: Closing Stock | L6: Stock Shortfall | M6: Reorder Lines | O6: Outlet | P6: Avg Utilization % | Q6: Lines > 100% | V6: helper: low-utilization list
B7: BrewBean RS Puram | C7: =SUMIFS(Inventory_Clean!$I$2:$I$501,Inventory_Clean!$C$2:$C$501,$B7) | D7: =IFERROR(C7/C$17,0) | F7: BrewBean Trichy | G7: =SUMIFS(Inventory_Clean!$J$2:$J$501,Inventory_Clean!$C$2:$C$501,$F7) | H7: =IFERROR(SUMIFS(Inventory_Clean!$J$2:$J$501,Inventory_Clean!$C$2:$C$501,$F7)/SUMIFS(Inventory_Clean!$O$2:$O$501,Inventory_Clean!$C$2:$C$501,$F7),0) | J7: BrewBean Pollachi | K7: =SUMIFS(Inventory_Clean!$Q$2:$Q$501,Inventory_Clean!$C$2:$C$501,$J7) | L7: =SUMIFS(Inventory_Clean!$R$2:$R$501,Inventory_Clean!$C$2:$C$501,$J7) | M7: =COUNTIFS(Inventory_Clean!$C$2:$C$501,$J7,Inventory_Clean!$U$2:$U$501,"Reorder Required") | O7: BrewBean RS Puram | P7: =IFERROR(AVERAGEIFS(Inventory_Clean!$T$2:$T$501,Inventory_Clean!$C$2:$C$501,$O7),0) | Q7: =COUNTIFS(Inventory_Clean!$C$2:$C$501,$O7,Inventory_Clean!$T$2:$T$501,">1") | V7: =IF(P7<$P$17,MID(O7,10,40),"")
B8: BrewBean Saravanampatti | C8: =SUMIFS(Inventory_Clean!$I$2:$I$501,Inventory_Clean!$C$2:$C$501,$B8) | D8: =IFERROR(C8/C$17,0) | F8: BrewBean Peelamedu | G8: =SUMIFS(Inventory_Clean!$J$2:$J$501,Inventory_Clean!$C$2:$C$501,$F8) | H8: =IFERROR(SUMIFS(Inventory_Clean!$J$2:$J$501,Inventory_Clean!$C$2:$C$501,$F8)/SUMIFS(Inventory_Clean!$O$2:$O$501,Inventory_Clean!$C$2:$C$501,$F8),0) | J8: BrewBean Tiruppur | K8: =SUMIFS(Inventory_Clean!$Q$2:$Q$501,Inventory_Clean!$C$2:$C$501,$J8) | L8: =SUMIFS(Inventory_Clean!$R$2:$R$501,Inventory_Clean!$C$2:$C$501,$J8) | M8: =COUNTIFS(Inventory_Clean!$C$2:$C$501,$J8,Inventory_Clean!$U$2:$U$501,"Reorder Required") | O8: BrewBean Saravanampatti | P8: =IFERROR(AVERAGEIFS(Inventory_Clean!$T$2:$T$501,Inventory_Clean!$C$2:$C$501,$O8),0) | Q8: =COUNTIFS(Inventory_Clean!$C$2:$C$501,$O8,Inventory_Clean!$T$2:$T$501,">1") | V8: =IF(P8<$P$17,IF(V7="","",V7&", ")&MID(O8,10,40),V7)
B9: BrewBean Saibaba Colony | C9: =SUMIFS(Inventory_Clean!$I$2:$I$501,Inventory_Clean!$C$2:$C$501,$B9) | D9: =IFERROR(C9/C$17,0) | F9: BrewBean Salem | G9: =SUMIFS(Inventory_Clean!$J$2:$J$501,Inventory_Clean!$C$2:$C$501,$F9) | H9: =IFERROR(SUMIFS(Inventory_Clean!$J$2:$J$501,Inventory_Clean!$C$2:$C$501,$F9)/SUMIFS(Inventory_Clean!$O$2:$O$501,Inventory_Clean!$C$2:$C$501,$F9),0) | J9: BrewBean Peelamedu | K9: =SUMIFS(Inventory_Clean!$Q$2:$Q$501,Inventory_Clean!$C$2:$C$501,$J9) | L9: =SUMIFS(Inventory_Clean!$R$2:$R$501,Inventory_Clean!$C$2:$C$501,$J9) | M9: =COUNTIFS(Inventory_Clean!$C$2:$C$501,$J9,Inventory_Clean!$U$2:$U$501,"Reorder Required") | O9: BrewBean Saibaba Colony | P9: =IFERROR(AVERAGEIFS(Inventory_Clean!$T$2:$T$501,Inventory_Clean!$C$2:$C$501,$O9),0) | Q9: =COUNTIFS(Inventory_Clean!$C$2:$C$501,$O9,Inventory_Clean!$T$2:$T$501,">1") | V9: =IF(P9<$P$17,IF(V8="","",V8&", ")&MID(O9,10,40),V8)
B10: BrewBean Gandhipuram | C10: =SUMIFS(Inventory_Clean!$I$2:$I$501,Inventory_Clean!$C$2:$C$501,$B10) | D10: =IFERROR(C10/C$17,0) | F10: BrewBean Madurai | G10: =SUMIFS(Inventory_Clean!$J$2:$J$501,Inventory_Clean!$C$2:$C$501,$F10) | H10: =IFERROR(SUMIFS(Inventory_Clean!$J$2:$J$501,Inventory_Clean!$C$2:$C$501,$F10)/SUMIFS(Inventory_Clean!$O$2:$O$501,Inventory_Clean!$C$2:$C$501,$F10),0) | J10: BrewBean Salem | K10: =SUMIFS(Inventory_Clean!$Q$2:$Q$501,Inventory_Clean!$C$2:$C$501,$J10) | L10: =SUMIFS(Inventory_Clean!$R$2:$R$501,Inventory_Clean!$C$2:$C$501,$J10) | M10: =COUNTIFS(Inventory_Clean!$C$2:$C$501,$J10,Inventory_Clean!$U$2:$U$501,"Reorder Required") | O10: BrewBean Trichy | P10: =IFERROR(AVERAGEIFS(Inventory_Clean!$T$2:$T$501,Inventory_Clean!$C$2:$C$501,$O10),0) | Q10: =COUNTIFS(Inventory_Clean!$C$2:$C$501,$O10,Inventory_Clean!$T$2:$T$501,">1") | V10: =IF(P10<$P$17,IF(V9="","",V9&", ")&MID(O10,10,40),V9)
B11: BrewBean Trichy | C11: =SUMIFS(Inventory_Clean!$I$2:$I$501,Inventory_Clean!$C$2:$C$501,$B11) | D11: =IFERROR(C11/C$17,0) | F11: BrewBean Gandhipuram | G11: =SUMIFS(Inventory_Clean!$J$2:$J$501,Inventory_Clean!$C$2:$C$501,$F11) | H11: =IFERROR(SUMIFS(Inventory_Clean!$J$2:$J$501,Inventory_Clean!$C$2:$C$501,$F11)/SUMIFS(Inventory_Clean!$O$2:$O$501,Inventory_Clean!$C$2:$C$501,$F11),0) | J11: BrewBean Gandhipuram | K11: =SUMIFS(Inventory_Clean!$Q$2:$Q$501,Inventory_Clean!$C$2:$C$501,$J11) | L11: =SUMIFS(Inventory_Clean!$R$2:$R$501,Inventory_Clean!$C$2:$C$501,$J11) | M11: =COUNTIFS(Inventory_Clean!$C$2:$C$501,$J11,Inventory_Clean!$U$2:$U$501,"Reorder Required") | O11: BrewBean Madurai | P11: =IFERROR(AVERAGEIFS(Inventory_Clean!$T$2:$T$501,Inventory_Clean!$C$2:$C$501,$O11),0) | Q11: =COUNTIFS(Inventory_Clean!$C$2:$C$501,$O11,Inventory_Clean!$T$2:$T$501,">1") | V11: =IF(P11<$P$17,IF(V10="","",V10&", ")&MID(O11,10,40),V10)
B12: BrewBean Madurai | C12: =SUMIFS(Inventory_Clean!$I$2:$I$501,Inventory_Clean!$C$2:$C$501,$B12) | D12: =IFERROR(C12/C$17,0) | F12: BrewBean Tiruppur | G12: =SUMIFS(Inventory_Clean!$J$2:$J$501,Inventory_Clean!$C$2:$C$501,$F12) | H12: =IFERROR(SUMIFS(Inventory_Clean!$J$2:$J$501,Inventory_Clean!$C$2:$C$501,$F12)/SUMIFS(Inventory_Clean!$O$2:$O$501,Inventory_Clean!$C$2:$C$501,$F12),0) | J12: BrewBean Trichy | K12: =SUMIFS(Inventory_Clean!$Q$2:$Q$501,Inventory_Clean!$C$2:$C$501,$J12) | L12: =SUMIFS(Inventory_Clean!$R$2:$R$501,Inventory_Clean!$C$2:$C$501,$J12) | M12: =COUNTIFS(Inventory_Clean!$C$2:$C$501,$J12,Inventory_Clean!$U$2:$U$501,"Reorder Required") | O12: BrewBean Gandhipuram | P12: =IFERROR(AVERAGEIFS(Inventory_Clean!$T$2:$T$501,Inventory_Clean!$C$2:$C$501,$O12),0) | Q12: =COUNTIFS(Inventory_Clean!$C$2:$C$501,$O12,Inventory_Clean!$T$2:$T$501,">1") | V12: =IF(P12<$P$17,IF(V11="","",V11&", ")&MID(O12,10,40),V11)
B13: BrewBean Tiruppur | C13: =SUMIFS(Inventory_Clean!$I$2:$I$501,Inventory_Clean!$C$2:$C$501,$B13) | D13: =IFERROR(C13/C$17,0) | F13: BrewBean RS Puram | G13: =SUMIFS(Inventory_Clean!$J$2:$J$501,Inventory_Clean!$C$2:$C$501,$F13) | H13: =IFERROR(SUMIFS(Inventory_Clean!$J$2:$J$501,Inventory_Clean!$C$2:$C$501,$F13)/SUMIFS(Inventory_Clean!$O$2:$O$501,Inventory_Clean!$C$2:$C$501,$F13),0) | J13: BrewBean Saibaba Colony | K13: =SUMIFS(Inventory_Clean!$Q$2:$Q$501,Inventory_Clean!$C$2:$C$501,$J13) | L13: =SUMIFS(Inventory_Clean!$R$2:$R$501,Inventory_Clean!$C$2:$C$501,$J13) | M13: =COUNTIFS(Inventory_Clean!$C$2:$C$501,$J13,Inventory_Clean!$U$2:$U$501,"Reorder Required") | O13: BrewBean Peelamedu | P13: =IFERROR(AVERAGEIFS(Inventory_Clean!$T$2:$T$501,Inventory_Clean!$C$2:$C$501,$O13),0) | Q13: =COUNTIFS(Inventory_Clean!$C$2:$C$501,$O13,Inventory_Clean!$T$2:$T$501,">1") | V13: =IF(P13<$P$17,IF(V12="","",V12&", ")&MID(O13,10,40),V12)
B14: BrewBean Peelamedu | C14: =SUMIFS(Inventory_Clean!$I$2:$I$501,Inventory_Clean!$C$2:$C$501,$B14) | D14: =IFERROR(C14/C$17,0) | F14: BrewBean Saibaba Colony | G14: =SUMIFS(Inventory_Clean!$J$2:$J$501,Inventory_Clean!$C$2:$C$501,$F14) | H14: =IFERROR(SUMIFS(Inventory_Clean!$J$2:$J$501,Inventory_Clean!$C$2:$C$501,$F14)/SUMIFS(Inventory_Clean!$O$2:$O$501,Inventory_Clean!$C$2:$C$501,$F14),0) | J14: BrewBean Madurai | K14: =SUMIFS(Inventory_Clean!$Q$2:$Q$501,Inventory_Clean!$C$2:$C$501,$J14) | L14: =SUMIFS(Inventory_Clean!$R$2:$R$501,Inventory_Clean!$C$2:$C$501,$J14) | M14: =COUNTIFS(Inventory_Clean!$C$2:$C$501,$J14,Inventory_Clean!$U$2:$U$501,"Reorder Required") | O14: BrewBean Tiruppur | P14: =IFERROR(AVERAGEIFS(Inventory_Clean!$T$2:$T$501,Inventory_Clean!$C$2:$C$501,$O14),0) | Q14: =COUNTIFS(Inventory_Clean!$C$2:$C$501,$O14,Inventory_Clean!$T$2:$T$501,">1") | V14: =IF(P14<$P$17,IF(V13="","",V13&", ")&MID(O14,10,40),V13)
B15: BrewBean Salem | C15: =SUMIFS(Inventory_Clean!$I$2:$I$501,Inventory_Clean!$C$2:$C$501,$B15) | D15: =IFERROR(C15/C$17,0) | F15: BrewBean Saravanampatti | G15: =SUMIFS(Inventory_Clean!$J$2:$J$501,Inventory_Clean!$C$2:$C$501,$F15) | H15: =IFERROR(SUMIFS(Inventory_Clean!$J$2:$J$501,Inventory_Clean!$C$2:$C$501,$F15)/SUMIFS(Inventory_Clean!$O$2:$O$501,Inventory_Clean!$C$2:$C$501,$F15),0) | J15: BrewBean Saravanampatti | K15: =SUMIFS(Inventory_Clean!$Q$2:$Q$501,Inventory_Clean!$C$2:$C$501,$J15) | L15: =SUMIFS(Inventory_Clean!$R$2:$R$501,Inventory_Clean!$C$2:$C$501,$J15) | M15: =COUNTIFS(Inventory_Clean!$C$2:$C$501,$J15,Inventory_Clean!$U$2:$U$501,"Reorder Required") | O15: BrewBean Salem | P15: =IFERROR(AVERAGEIFS(Inventory_Clean!$T$2:$T$501,Inventory_Clean!$C$2:$C$501,$O15),0) | Q15: =COUNTIFS(Inventory_Clean!$C$2:$C$501,$O15,Inventory_Clean!$T$2:$T$501,">1") | V15: =IF(P15<$P$17,IF(V14="","",V14&", ")&MID(O15,10,40),V14)
B16: BrewBean Pollachi | C16: =SUMIFS(Inventory_Clean!$I$2:$I$501,Inventory_Clean!$C$2:$C$501,$B16) | D16: =IFERROR(C16/C$17,0) | F16: BrewBean Pollachi | G16: =SUMIFS(Inventory_Clean!$J$2:$J$501,Inventory_Clean!$C$2:$C$501,$F16) | H16: =IFERROR(SUMIFS(Inventory_Clean!$J$2:$J$501,Inventory_Clean!$C$2:$C$501,$F16)/SUMIFS(Inventory_Clean!$O$2:$O$501,Inventory_Clean!$C$2:$C$501,$F16),0) | J16: BrewBean RS Puram | K16: =SUMIFS(Inventory_Clean!$Q$2:$Q$501,Inventory_Clean!$C$2:$C$501,$J16) | L16: =SUMIFS(Inventory_Clean!$R$2:$R$501,Inventory_Clean!$C$2:$C$501,$J16) | M16: =COUNTIFS(Inventory_Clean!$C$2:$C$501,$J16,Inventory_Clean!$U$2:$U$501,"Reorder Required") | O16: BrewBean Pollachi | P16: =IFERROR(AVERAGEIFS(Inventory_Clean!$T$2:$T$501,Inventory_Clean!$C$2:$C$501,$O16),0) | Q16: =COUNTIFS(Inventory_Clean!$C$2:$C$501,$O16,Inventory_Clean!$T$2:$T$501,">1") | V16: =IF(P16<$P$17,IF(V15="","",V15&", ")&MID(O16,10,40),V15)
B17: Grand Total | C17: =SUM(C7:C16) | D17: =SUM(D7:D16) | F17: Grand Total | G17: =SUM(G7:G16) | H17: =IFERROR(SUM(Inventory_Clean!$J$2:$J$501)/SUM(Inventory_Clean!$O$2:$O$501),0) | J17: Grand Total | K17: =SUM(K7:K16) | L17: =SUM(L7:L16) | M17: =SUM(M7:M16) | O17: Grand Total | P17: =AVERAGE(Inventory_Clean!$T$2:$T$501) | Q17: =SUM(Q7:Q16)
B20: 9a · Supplier Lead Time by Outlet (days) | F20: 9b · Supplier Lead Time by Category (days) | K20: 8 · Inventory Movement by Outlet (stock flow)
B21: Outlet | C21: Avg Days | D21: Min | E21: Max | F21: Category | G21: Avg Days | H21: Min | I21: Max | K21: Outlet | L21: Opening Stock | M21: Received | N21: Units Sold | O21: Wastage | P21: Closing Stock
B22: BrewBean Trichy | C22: =IFERROR(AVERAGEIFS(Inventory_Clean!$L$2:$L$501,Inventory_Clean!$C$2:$C$501,$B22),0) | D22: =_xlfn.MINIFS(Inventory_Clean!$L$2:$L$501,Inventory_Clean!$C$2:$C$501,$B22) | E22: =_xlfn.MAXIFS(Inventory_Clean!$L$2:$L$501,Inventory_Clean!$C$2:$C$501,$B22) | F22: Coffee | G22: =IFERROR(AVERAGEIFS(Inventory_Clean!$L$2:$L$501,Inventory_Clean!$F$2:$F$501,$F22),0) | H22: =_xlfn.MINIFS(Inventory_Clean!$L$2:$L$501,Inventory_Clean!$F$2:$F$501,$F22) | I22: =_xlfn.MAXIFS(Inventory_Clean!$L$2:$L$501,Inventory_Clean!$F$2:$F$501,$F22) | K22: BrewBean RS Puram | L22: =SUMIFS(Inventory_Clean!$G$2:$G$501,Inventory_Clean!$C$2:$C$501,$K22) | M22: =SUMIFS(Inventory_Clean!$H$2:$H$501,Inventory_Clean!$C$2:$C$501,$K22) | N22: =SUMIFS(Inventory_Clean!$I$2:$I$501,Inventory_Clean!$C$2:$C$501,$K22) | O22: =SUMIFS(Inventory_Clean!$J$2:$J$501,Inventory_Clean!$C$2:$C$501,$K22) | P22: =SUMIFS(Inventory_Clean!$Q$2:$Q$501,Inventory_Clean!$C$2:$C$501,$K22)
B23: BrewBean Saibaba Colony | C23: =IFERROR(AVERAGEIFS(Inventory_Clean!$L$2:$L$501,Inventory_Clean!$C$2:$C$501,$B23),0) | D23: =_xlfn.MINIFS(Inventory_Clean!$L$2:$L$501,Inventory_Clean!$C$2:$C$501,$B23) | E23: =_xlfn.MAXIFS(Inventory_Clean!$L$2:$L$501,Inventory_Clean!$C$2:$C$501,$B23) | F23: Tea | G23: =IFERROR(AVERAGEIFS(Inventory_Clean!$L$2:$L$501,Inventory_Clean!$F$2:$F$501,$F23),0) | H23: =_xlfn.MINIFS(Inventory_Clean!$L$2:$L$501,Inventory_Clean!$F$2:$F$501,$F23) | I23: =_xlfn.MAXIFS(Inventory_Clean!$L$2:$L$501,Inventory_Clean!$F$2:$F$501,$F23) | K23: BrewBean Saravanampatti | L23: =SUMIFS(Inventory_Clean!$G$2:$G$501,Inventory_Clean!$C$2:$C$501,$K23) | M23: =SUMIFS(Inventory_Clean!$H$2:$H$501,Inventory_Clean!$C$2:$C$501,$K23) | N23: =SUMIFS(Inventory_Clean!$I$2:$I$501,Inventory_Clean!$C$2:$C$501,$K23) | O23: =SUMIFS(Inventory_Clean!$J$2:$J$501,Inventory_Clean!$C$2:$C$501,$K23) | P23: =SUMIFS(Inventory_Clean!$Q$2:$Q$501,Inventory_Clean!$C$2:$C$501,$K23)
B24: BrewBean Tiruppur | C24: =IFERROR(AVERAGEIFS(Inventory_Clean!$L$2:$L$501,Inventory_Clean!$C$2:$C$501,$B24),0) | D24: =_xlfn.MINIFS(Inventory_Clean!$L$2:$L$501,Inventory_Clean!$C$2:$C$501,$B24) | E24: =_xlfn.MAXIFS(Inventory_Clean!$L$2:$L$501,Inventory_Clean!$C$2:$C$501,$B24) | F24: Sandwich | G24: =IFERROR(AVERAGEIFS(Inventory_Clean!$L$2:$L$501,Inventory_Clean!$F$2:$F$501,$F24),0) | H24: =_xlfn.MINIFS(Inventory_Clean!$L$2:$L$501,Inventory_Clean!$F$2:$F$501,$F24) | I24: =_xlfn.MAXIFS(Inventory_Clean!$L$2:$L$501,Inventory_Clean!$F$2:$F$501,$F24) | K24: BrewBean Saibaba Colony | L24: =SUMIFS(Inventory_Clean!$G$2:$G$501,Inventory_Clean!$C$2:$C$501,$K24) | M24: =SUMIFS(Inventory_Clean!$H$2:$H$501,Inventory_Clean!$C$2:$C$501,$K24) | N24: =SUMIFS(Inventory_Clean!$I$2:$I$501,Inventory_Clean!$C$2:$C$501,$K24) | O24: =SUMIFS(Inventory_Clean!$J$2:$J$501,Inventory_Clean!$C$2:$C$501,$K24) | P24: =SUMIFS(Inventory_Clean!$Q$2:$Q$501,Inventory_Clean!$C$2:$C$501,$K24)
B25: BrewBean Pollachi | C25: =IFERROR(AVERAGEIFS(Inventory_Clean!$L$2:$L$501,Inventory_Clean!$C$2:$C$501,$B25),0) | D25: =_xlfn.MINIFS(Inventory_Clean!$L$2:$L$501,Inventory_Clean!$C$2:$C$501,$B25) | E25: =_xlfn.MAXIFS(Inventory_Clean!$L$2:$L$501,Inventory_Clean!$C$2:$C$501,$B25) | F25: Burger | G25: =IFERROR(AVERAGEIFS(Inventory_Clean!$L$2:$L$501,Inventory_Clean!$F$2:$F$501,$F25),0) | H25: =_xlfn.MINIFS(Inventory_Clean!$L$2:$L$501,Inventory_Clean!$F$2:$F$501,$F25) | I25: =_xlfn.MAXIFS(Inventory_Clean!$L$2:$L$501,Inventory_Clean!$F$2:$F$501,$F25) | K25: BrewBean Gandhipuram | L25: =SUMIFS(Inventory_Clean!$G$2:$G$501,Inventory_Clean!$C$2:$C$501,$K25) | M25: =SUMIFS(Inventory_Clean!$H$2:$H$501,Inventory_Clean!$C$2:$C$501,$K25) | N25: =SUMIFS(Inventory_Clean!$I$2:$I$501,Inventory_Clean!$C$2:$C$501,$K25) | O25: =SUMIFS(Inventory_Clean!$J$2:$J$501,Inventory_Clean!$C$2:$C$501,$K25) | P25: =SUMIFS(Inventory_Clean!$Q$2:$Q$501,Inventory_Clean!$C$2:$C$501,$K25)
B26: BrewBean Gandhipuram | C26: =IFERROR(AVERAGEIFS(Inventory_Clean!$L$2:$L$501,Inventory_Clean!$C$2:$C$501,$B26),0) | D26: =_xlfn.MINIFS(Inventory_Clean!$L$2:$L$501,Inventory_Clean!$C$2:$C$501,$B26) | E26: =_xlfn.MAXIFS(Inventory_Clean!$L$2:$L$501,Inventory_Clean!$C$2:$C$501,$B26) | F26: Wrap | G26: =IFERROR(AVERAGEIFS(Inventory_Clean!$L$2:$L$501,Inventory_Clean!$F$2:$F$501,$F26),0) | H26: =_xlfn.MINIFS(Inventory_Clean!$L$2:$L$501,Inventory_Clean!$F$2:$F$501,$F26) | I26: =_xlfn.MAXIFS(Inventory_Clean!$L$2:$L$501,Inventory_Clean!$F$2:$F$501,$F26) | K26: BrewBean Trichy | L26: =SUMIFS(Inventory_Clean!$G$2:$G$501,Inventory_Clean!$C$2:$C$501,$K26) | M26: =SUMIFS(Inventory_Clean!$H$2:$H$501,Inventory_Clean!$C$2:$C$501,$K26) | N26: =SUMIFS(Inventory_Clean!$I$2:$I$501,Inventory_Clean!$C$2:$C$501,$K26) | O26: =SUMIFS(Inventory_Clean!$J$2:$J$501,Inventory_Clean!$C$2:$C$501,$K26) | P26: =SUMIFS(Inventory_Clean!$Q$2:$Q$501,Inventory_Clean!$C$2:$C$501,$K26)
B27: BrewBean Peelamedu | C27: =IFERROR(AVERAGEIFS(Inventory_Clean!$L$2:$L$501,Inventory_Clean!$C$2:$C$501,$B27),0) | D27: =_xlfn.MINIFS(Inventory_Clean!$L$2:$L$501,Inventory_Clean!$C$2:$C$501,$B27) | E27: =_xlfn.MAXIFS(Inventory_Clean!$L$2:$L$501,Inventory_Clean!$C$2:$C$501,$B27) | F27: Smoothie | G27: =IFERROR(AVERAGEIFS(Inventory_Clean!$L$2:$L$501,Inventory_Clean!$F$2:$F$501,$F27),0) | H27: =_xlfn.MINIFS(Inventory_Clean!$L$2:$L$501,Inventory_Clean!$F$2:$F$501,$F27) | I27: =_xlfn.MAXIFS(Inventory_Clean!$L$2:$L$501,Inventory_Clean!$F$2:$F$501,$F27) | K27: BrewBean Madurai | L27: =SUMIFS(Inventory_Clean!$G$2:$G$501,Inventory_Clean!$C$2:$C$501,$K27) | M27: =SUMIFS(Inventory_Clean!$H$2:$H$501,Inventory_Clean!$C$2:$C$501,$K27) | N27: =SUMIFS(Inventory_Clean!$I$2:$I$501,Inventory_Clean!$C$2:$C$501,$K27) | O27: =SUMIFS(Inventory_Clean!$J$2:$J$501,Inventory_Clean!$C$2:$C$501,$K27) | P27: =SUMIFS(Inventory_Clean!$Q$2:$Q$501,Inventory_Clean!$C$2:$C$501,$K27)
B28: BrewBean Madurai | C28: =IFERROR(AVERAGEIFS(Inventory_Clean!$L$2:$L$501,Inventory_Clean!$C$2:$C$501,$B28),0) | D28: =_xlfn.MINIFS(Inventory_Clean!$L$2:$L$501,Inventory_Clean!$C$2:$C$501,$B28) | E28: =_xlfn.MAXIFS(Inventory_Clean!$L$2:$L$501,Inventory_Clean!$C$2:$C$501,$B28) | F28: Dessert | G28: =IFERROR(AVERAGEIFS(Inventory_Clean!$L$2:$L$501,Inventory_Clean!$F$2:$F$501,$F28),0) | H28: =_xlfn.MINIFS(Inventory_Clean!$L$2:$L$501,Inventory_Clean!$F$2:$F$501,$F28) | I28: =_xlfn.MAXIFS(Inventory_Clean!$L$2:$L$501,Inventory_Clean!$F$2:$F$501,$F28) | K28: BrewBean Tiruppur | L28: =SUMIFS(Inventory_Clean!$G$2:$G$501,Inventory_Clean!$C$2:$C$501,$K28) | M28: =SUMIFS(Inventory_Clean!$H$2:$H$501,Inventory_Clean!$C$2:$C$501,$K28) | N28: =SUMIFS(Inventory_Clean!$I$2:$I$501,Inventory_Clean!$C$2:$C$501,$K28) | O28: =SUMIFS(Inventory_Clean!$J$2:$J$501,Inventory_Clean!$C$2:$C$501,$K28) | P28: =SUMIFS(Inventory_Clean!$Q$2:$Q$501,Inventory_Clean!$C$2:$C$501,$K28)
B29: BrewBean Salem | C29: =IFERROR(AVERAGEIFS(Inventory_Clean!$L$2:$L$501,Inventory_Clean!$C$2:$C$501,$B29),0) | D29: =_xlfn.MINIFS(Inventory_Clean!$L$2:$L$501,Inventory_Clean!$C$2:$C$501,$B29) | E29: =_xlfn.MAXIFS(Inventory_Clean!$L$2:$L$501,Inventory_Clean!$C$2:$C$501,$B29) | F29: Fresh Juice | G29: =IFERROR(AVERAGEIFS(Inventory_Clean!$L$2:$L$501,Inventory_Clean!$F$2:$F$501,$F29),0) | H29: =_xlfn.MINIFS(Inventory_Clean!$L$2:$L$501,Inventory_Clean!$F$2:$F$501,$F29) | I29: =_xlfn.MAXIFS(Inventory_Clean!$L$2:$L$501,Inventory_Clean!$F$2:$F$501,$F29) | K29: BrewBean Peelamedu | L29: =SUMIFS(Inventory_Clean!$G$2:$G$501,Inventory_Clean!$C$2:$C$501,$K29) | M29: =SUMIFS(Inventory_Clean!$H$2:$H$501,Inventory_Clean!$C$2:$C$501,$K29) | N29: =SUMIFS(Inventory_Clean!$I$2:$I$501,Inventory_Clean!$C$2:$C$501,$K29) | O29: =SUMIFS(Inventory_Clean!$J$2:$J$501,Inventory_Clean!$C$2:$C$501,$K29) | P29: =SUMIFS(Inventory_Clean!$Q$2:$Q$501,Inventory_Clean!$C$2:$C$501,$K29)
B30: BrewBean Saravanampatti | C30: =IFERROR(AVERAGEIFS(Inventory_Clean!$L$2:$L$501,Inventory_Clean!$C$2:$C$501,$B30),0) | D30: =_xlfn.MINIFS(Inventory_Clean!$L$2:$L$501,Inventory_Clean!$C$2:$C$501,$B30) | E30: =_xlfn.MAXIFS(Inventory_Clean!$L$2:$L$501,Inventory_Clean!$C$2:$C$501,$B30) | F30: Beverage | G30: =IFERROR(AVERAGEIFS(Inventory_Clean!$L$2:$L$501,Inventory_Clean!$F$2:$F$501,$F30),0) | H30: =_xlfn.MINIFS(Inventory_Clean!$L$2:$L$501,Inventory_Clean!$F$2:$F$501,$F30) | I30: =_xlfn.MAXIFS(Inventory_Clean!$L$2:$L$501,Inventory_Clean!$F$2:$F$501,$F30) | K30: BrewBean Salem | L30: =SUMIFS(Inventory_Clean!$G$2:$G$501,Inventory_Clean!$C$2:$C$501,$K30) | M30: =SUMIFS(Inventory_Clean!$H$2:$H$501,Inventory_Clean!$C$2:$C$501,$K30) | N30: =SUMIFS(Inventory_Clean!$I$2:$I$501,Inventory_Clean!$C$2:$C$501,$K30) | O30: =SUMIFS(Inventory_Clean!$J$2:$J$501,Inventory_Clean!$C$2:$C$501,$K30) | P30: =SUMIFS(Inventory_Clean!$Q$2:$Q$501,Inventory_Clean!$C$2:$C$501,$K30)
B31: BrewBean RS Puram | C31: =IFERROR(AVERAGEIFS(Inventory_Clean!$L$2:$L$501,Inventory_Clean!$C$2:$C$501,$B31),0) | D31: =_xlfn.MINIFS(Inventory_Clean!$L$2:$L$501,Inventory_Clean!$C$2:$C$501,$B31) | E31: =_xlfn.MAXIFS(Inventory_Clean!$L$2:$L$501,Inventory_Clean!$C$2:$C$501,$B31) | F31: Cold Coffee | G31: =IFERROR(AVERAGEIFS(Inventory_Clean!$L$2:$L$501,Inventory_Clean!$F$2:$F$501,$F31),0) | H31: =_xlfn.MINIFS(Inventory_Clean!$L$2:$L$501,Inventory_Clean!$F$2:$F$501,$F31) | I31: =_xlfn.MAXIFS(Inventory_Clean!$L$2:$L$501,Inventory_Clean!$F$2:$F$501,$F31) | K31: BrewBean Pollachi | L31: =SUMIFS(Inventory_Clean!$G$2:$G$501,Inventory_Clean!$C$2:$C$501,$K31) | M31: =SUMIFS(Inventory_Clean!$H$2:$H$501,Inventory_Clean!$C$2:$C$501,$K31) | N31: =SUMIFS(Inventory_Clean!$I$2:$I$501,Inventory_Clean!$C$2:$C$501,$K31) | O31: =SUMIFS(Inventory_Clean!$J$2:$J$501,Inventory_Clean!$C$2:$C$501,$K31) | P31: =SUMIFS(Inventory_Clean!$Q$2:$Q$501,Inventory_Clean!$C$2:$C$501,$K31)
B32: Grand Total | C32: =AVERAGE(Inventory_Clean!$L$2:$L$501) | D32: =MIN(Inventory_Clean!$L$2:$L$501) | E32: =MAX(Inventory_Clean!$L$2:$L$501) | F32: Cake | G32: =IFERROR(AVERAGEIFS(Inventory_Clean!$L$2:$L$501,Inventory_Clean!$F$2:$F$501,$F32),0) | H32: =_xlfn.MINIFS(Inventory_Clean!$L$2:$L$501,Inventory_Clean!$F$2:$F$501,$F32) | I32: =_xlfn.MAXIFS(Inventory_Clean!$L$2:$L$501,Inventory_Clean!$F$2:$F$501,$F32) | K32: Grand Total | L32: =SUM(L22:L31) | M32: =SUM(M22:M31) | N32: =SUM(N22:N31) | O32: =SUM(O22:O31) | P32: =SUM(P22:P31)
F33: Cookies | G33: =IFERROR(AVERAGEIFS(Inventory_Clean!$L$2:$L$501,Inventory_Clean!$F$2:$F$501,$F33),0) | H33: =_xlfn.MINIFS(Inventory_Clean!$L$2:$L$501,Inventory_Clean!$F$2:$F$501,$F33) | I33: =_xlfn.MAXIFS(Inventory_Clean!$L$2:$L$501,Inventory_Clean!$F$2:$F$501,$F33)
F34: Pastry | G34: =IFERROR(AVERAGEIFS(Inventory_Clean!$L$2:$L$501,Inventory_Clean!$F$2:$F$501,$F34),0) | H34: =_xlfn.MINIFS(Inventory_Clean!$L$2:$L$501,Inventory_Clean!$F$2:$F$501,$F34) | I34: =_xlfn.MAXIFS(Inventory_Clean!$L$2:$L$501,Inventory_Clean!$F$2:$F$501,$F34)
F35: Frappes | G35: =IFERROR(AVERAGEIFS(Inventory_Clean!$L$2:$L$501,Inventory_Clean!$F$2:$F$501,$F35),0) | H35: =_xlfn.MINIFS(Inventory_Clean!$L$2:$L$501,Inventory_Clean!$F$2:$F$501,$F35) | I35: =_xlfn.MAXIFS(Inventory_Clean!$L$2:$L$501,Inventory_Clean!$F$2:$F$501,$F35)
F36: Sides | G36: =IFERROR(AVERAGEIFS(Inventory_Clean!$L$2:$L$501,Inventory_Clean!$F$2:$F$501,$F36),0) | H36: =_xlfn.MINIFS(Inventory_Clean!$L$2:$L$501,Inventory_Clean!$F$2:$F$501,$F36) | I36: =_xlfn.MAXIFS(Inventory_Clean!$L$2:$L$501,Inventory_Clean!$F$2:$F$501,$F36)
F37: Grand Total | G37: =AVERAGE(Inventory_Clean!$L$2:$L$501) | H37: =MIN(Inventory_Clean!$L$2:$L$501) | I37: =MAX(Inventory_Clean!$L$2:$L$501)
B40: 2 · Units Sold by Product | G40: 4 · Wastage by Product | K40: 6 · Reorder Status by Product | Q40: Top 10 Products by Units Sold (dynamic)
B41: Product | C41: Category | D41: Units Sold | E41: rank key | G41: Product | H41: Wastage (units) | I41: Wastage % | J41: rank key | K41: Product | L41: Reorder Required | M41: Stock Sufficient | N41: % Reorder | O41: rank key | Q41: Rank | R41: Product | S41: Units Sold
B42: Product 16 | C42: =INDEX(Inventory_Clean!$F$2:$F$501,MATCH($B42,Inventory_Clean!$E$2:$E$501,0)) | D42: =SUMIFS(Inventory_Clean!$I$2:$I$501,Inventory_Clean!$E$2:$E$501,$B42) | E42: =D42+ROW()/1000000 | G42: Product 30 | H42: =SUMIFS(Inventory_Clean!$J$2:$J$501,Inventory_Clean!$E$2:$E$501,$G42) | I42: =IFERROR(SUMIFS(Inventory_Clean!$J$2:$J$501,Inventory_Clean!$E$2:$E$501,$G42)/SUMIFS(Inventory_Clean!$O$2:$O$501,Inventory_Clean!$E$2:$E$501,$G42),0) | J42: =H42+ROW()/1000000 | K42: Product 42 | L42: =COUNTIFS(Inventory_Clean!$E$2:$E$501,$K42,Inventory_Clean!$U$2:$U$501,"Reorder Required") | M42: =COUNTIFS(Inventory_Clean!$E$2:$E$501,$K42,Inventory_Clean!$U$2:$U$501,"Stock Sufficient") | N42: =IFERROR(L42/(L42+M42),0) | O42: =L42+ROW()/1000000 | Q42: 1 | R42: =INDEX($B$42:$B$91,MATCH(LARGE($E$42:$E$91,Q42),$E$42:$E$91,0)) | S42: =INDEX($D$42:$D$91,MATCH(LARGE($E$42:$E$91,Q42),$E$42:$E$91,0))
B43: Product 26 | C43: =INDEX(Inventory_Clean!$F$2:$F$501,MATCH($B43,Inventory_Clean!$E$2:$E$501,0)) | D43: =SUMIFS(Inventory_Clean!$I$2:$I$501,Inventory_Clean!$E$2:$E$501,$B43) | E43: =D43+ROW()/1000000 | G43: Product 31 | H43: =SUMIFS(Inventory_Clean!$J$2:$J$501,Inventory_Clean!$E$2:$E$501,$G43) | I43: =IFERROR(SUMIFS(Inventory_Clean!$J$2:$J$501,Inventory_Clean!$E$2:$E$501,$G43)/SUMIFS(Inventory_Clean!$O$2:$O$501,Inventory_Clean!$E$2:$E$501,$G43),0) | J43: =H43+ROW()/1000000 | K43: Product 44 | L43: =COUNTIFS(Inventory_Clean!$E$2:$E$501,$K43,Inventory_Clean!$U$2:$U$501,"Reorder Required") | M43: =COUNTIFS(Inventory_Clean!$E$2:$E$501,$K43,Inventory_Clean!$U$2:$U$501,"Stock Sufficient") | N43: =IFERROR(L43/(L43+M43),0) | O43: =L43+ROW()/1000000 | Q43: 2 | R43: =INDEX($B$42:$B$91,MATCH(LARGE($E$42:$E$91,Q43),$E$42:$E$91,0)) | S43: =INDEX($D$42:$D$91,MATCH(LARGE($E$42:$E$91,Q43),$E$42:$E$91,0))
B44: Product 20 | C44: =INDEX(Inventory_Clean!$F$2:$F$501,MATCH($B44,Inventory_Clean!$E$2:$E$501,0)) | D44: =SUMIFS(Inventory_Clean!$I$2:$I$501,Inventory_Clean!$E$2:$E$501,$B44) | E44: =D44+ROW()/1000000 | G44: Product 33 | H44: =SUMIFS(Inventory_Clean!$J$2:$J$501,Inventory_Clean!$E$2:$E$501,$G44) | I44: =IFERROR(SUMIFS(Inventory_Clean!$J$2:$J$501,Inventory_Clean!$E$2:$E$501,$G44)/SUMIFS(Inventory_Clean!$O$2:$O$501,Inventory_Clean!$E$2:$E$501,$G44),0) | J44: =H44+ROW()/1000000 | K44: Product 1 | L44: =COUNTIFS(Inventory_Clean!$E$2:$E$501,$K44,Inventory_Clean!$U$2:$U$501,"Reorder Required") | M44: =COUNTIFS(Inventory_Clean!$E$2:$E$501,$K44,Inventory_Clean!$U$2:$U$501,"Stock Sufficient") | N44: =IFERROR(L44/(L44+M44),0) | O44: =L44+ROW()/1000000 | Q44: 3 | R44: =INDEX($B$42:$B$91,MATCH(LARGE($E$42:$E$91,Q44),$E$42:$E$91,0)) | S44: =INDEX($D$42:$D$91,MATCH(LARGE($E$42:$E$91,Q44),$E$42:$E$91,0))
B45: Product 9 | C45: =INDEX(Inventory_Clean!$F$2:$F$501,MATCH($B45,Inventory_Clean!$E$2:$E$501,0)) | D45: =SUMIFS(Inventory_Clean!$I$2:$I$501,Inventory_Clean!$E$2:$E$501,$B45) | E45: =D45+ROW()/1000000 | G45: Product 39 | H45: =SUMIFS(Inventory_Clean!$J$2:$J$501,Inventory_Clean!$E$2:$E$501,$G45) | I45: =IFERROR(SUMIFS(Inventory_Clean!$J$2:$J$501,Inventory_Clean!$E$2:$E$501,$G45)/SUMIFS(Inventory_Clean!$O$2:$O$501,Inventory_Clean!$E$2:$E$501,$G45),0) | J45: =H45+ROW()/1000000 | K45: Product 20 | L45: =COUNTIFS(Inventory_Clean!$E$2:$E$501,$K45,Inventory_Clean!$U$2:$U$501,"Reorder Required") | M45: =COUNTIFS(Inventory_Clean!$E$2:$E$501,$K45,Inventory_Clean!$U$2:$U$501,"Stock Sufficient") | N45: =IFERROR(L45/(L45+M45),0) | O45: =L45+ROW()/1000000 | Q45: 4 | R45: =INDEX($B$42:$B$91,MATCH(LARGE($E$42:$E$91,Q45),$E$42:$E$91,0)) | S45: =INDEX($D$42:$D$91,MATCH(LARGE($E$42:$E$91,Q45),$E$42:$E$91,0))
B46: Product 37 | C46: =INDEX(Inventory_Clean!$F$2:$F$501,MATCH($B46,Inventory_Clean!$E$2:$E$501,0)) | D46: =SUMIFS(Inventory_Clean!$I$2:$I$501,Inventory_Clean!$E$2:$E$501,$B46) | E46: =D46+ROW()/1000000 | G46: Product 34 | H46: =SUMIFS(Inventory_Clean!$J$2:$J$501,Inventory_Clean!$E$2:$E$501,$G46) | I46: =IFERROR(SUMIFS(Inventory_Clean!$J$2:$J$501,Inventory_Clean!$E$2:$E$501,$G46)/SUMIFS(Inventory_Clean!$O$2:$O$501,Inventory_Clean!$E$2:$E$501,$G46),0) | J46: =H46+ROW()/1000000 | K46: Product 23 | L46: =COUNTIFS(Inventory_Clean!$E$2:$E$501,$K46,Inventory_Clean!$U$2:$U$501,"Reorder Required") | M46: =COUNTIFS(Inventory_Clean!$E$2:$E$501,$K46,Inventory_Clean!$U$2:$U$501,"Stock Sufficient") | N46: =IFERROR(L46/(L46+M46),0) | O46: =L46+ROW()/1000000 | Q46: 5 | R46: =INDEX($B$42:$B$91,MATCH(LARGE($E$42:$E$91,Q46),$E$42:$E$91,0)) | S46: =INDEX($D$42:$D$91,MATCH(LARGE($E$42:$E$91,Q46),$E$42:$E$91,0))
...

Sheet Inventory_Clean
A1: Inventory_ID | B1: Outlet_ID | C1: Outlet_Name | D1: Product_ID | E1: Product_Name | F1: Category | G1: Opening_Stock | H1: Received_Stock | I1: Units_Sold | J1: Wastage | K1: Reorder_Level | L1: Supplier_Lead_Time_Days | M1: Closing_Stock_Source | N1: Status_Source | O1: Stock_Available | P1: Closing_Stock | Q1: Closing_Stock_Adj | R1: Stock_Shortfall | S1: Wastage_% | T1: Stock_Utilization_% | U1: Reorder_Status | V1: Data_Check | W1: Remarks
A2: INV00001 | B2: OUT001 | C2: =INDEX(Lookup!$B$2:$B$11,MATCH(B2,Lookup!$A$2:$A$11,0)) | D2: BP001 | E2: =INDEX(Lookup!$E$2:$E$51,MATCH(D2,Lookup!$D$2:$D$51,0)) | F2: =INDEX(Lookup!$F$2:$F$51,MATCH(D2,Lookup!$D$2:$D$51,0)) | G2: 51 | H2: 71 | I2: 174 | J2: 0 | K2: 31 | L2: 1 | M2: 0 | N2: Reorder Required | O2: =G2+H2 | P2: =G2+H2-I2-J2 | Q2: =MAX(0,P2) | R2: =MAX(0,-P2) | S2: =IFERROR(J2/O2,0) | T2: =IFERROR(I2/O2,0) | U2: =IF(P2<=K2,"Reorder Required","Stock Sufficient") | V2: =IF(AND(Q2=M2,(U2="Reorder Required")=(N2="Reorder Required")),"OK","Mismatch") | W2: Restock immediately
A3: INV00002 | B3: OUT001 | C3: =INDEX(Lookup!$B$2:$B$11,MATCH(B3,Lookup!$A$2:$A$11,0)) | D3: BP002 | E3: =INDEX(Lookup!$E$2:$E$51,MATCH(D3,Lookup!$D$2:$D$51,0)) | F3: =INDEX(Lookup!$F$2:$F$51,MATCH(D3,Lookup!$D$2:$D$51,0)) | G3: 127 | H3: 96 | I3: 72 | J3: 2 | K3: 19 | L3: 4 | M3: 149 | N3: Healthy | O3: =G3+H3 | P3: =G3+H3-I3-J3 | Q3: =MAX(0,P3) | R3: =MAX(0,-P3) | S3: =IFERROR(J3/O3,0) | T3: =IFERROR(I3/O3,0) | U3: =IF(P3<=K3,"Reorder Required","Stock Sufficient") | V3: =IF(AND(Q3=M3,(U3="Reorder Required")=(N3="Reorder Required")),"OK","Mismatch")
A4: INV00003 | B4: OUT001 | C4: =INDEX(Lookup!$B$2:$B$11,MATCH(B4,Lookup!$A$2:$A$11,0)) | D4: BP003 | E4: =INDEX(Lookup!$E$2:$E$51,MATCH(D4,Lookup!$D$2:$D$51,0)) | F4: =INDEX(Lookup!$F$2:$F$51,MATCH(D4,Lookup!$D$2:$D$51,0)) | G4: 52 | H4: 22 | I4: 172 | J4: 3 | K4: 17 | L4: 5 | M4: 0 | N4: Reorder Required | O4: =G4+H4 | P4: =G4+H4-I4-J4 | Q4: =MAX(0,P4) | R4: =MAX(0,-P4) | S4: =IFERROR(J4/O4,0) | T4: =IFERROR(I4/O4,0) | U4: =IF(P4<=K4,"Reorder Required","Stock Sufficient") | V4: =IF(AND(Q4=M4,(U4="Reorder Required")=(N4="Reorder Required")),"OK","Mismatch") | W4: Restock immediately
A5: INV00004 | B5: OUT001 | C5: =INDEX(Lookup!$B$2:$B$11,MATCH(B5,Lookup!$A$2:$A$11,0)) | D5: BP004 | E5: =INDEX(Lookup!$E$2:$E$51,MATCH(D5,Lookup!$D$2:$D$51,0)) | F5: =INDEX(Lookup!$F$2:$F$51,MATCH(D5,Lookup!$D$2:$D$51,0)) | G5: 40 | H5: 42 | I5: 144 | J5: 1 | K5: 21 | L5: 2 | M5: 0 | N5: Reorder Required | O5: =G5+H5 | P5: =G5+H5-I5-J5 | Q5: =MAX(0,P5) | R5: =MAX(0,-P5) | S5: =IFERROR(J5/O5,0) | T5: =IFERROR(I5/O5,0) | U5: =IF(P5<=K5,"Reorder Required","Stock Sufficient") | V5: =IF(AND(Q5=M5,(U5="Reorder Required")=(N5="Reorder Required")),"OK","Mismatch") | W5: Restock immediately
A6: INV00005 | B6: OUT001 | C6: =INDEX(Lookup!$B$2:$B$11,MATCH(B6,Lookup!$A$2:$A$11,0)) | D6: BP005 | E6: =INDEX(Lookup!$E$2:$E$51,MATCH(D6,Lookup!$D$2:$D$51,0)) | F6: =INDEX(Lookup!$F$2:$F$51,MATCH(D6,Lookup!$D$2:$D$51,0)) | G6: 104 | H6: 36 | I6: 98 | J6: 3 | K6: 38 | L6: 3 | M6: 39 | N6: Healthy | O6: =G6+H6 | P6: =G6+H6-I6-J6 | Q6: =MAX(0,P6) | R6: =MAX(0,-P6) | S6: =IFERROR(J6/O6,0) | T6: =IFERROR(I6/O6,0) | U6: =IF(P6<=K6,"Reorder Required","Stock Sufficient") | V6: =IF(AND(Q6=M6,(U6="Reorder Required")=(N6="Reorder Required")),"OK","Mismatch")
A7: INV00006 | B7: OUT001 | C7: =INDEX(Lookup!$B$2:$B$11,MATCH(B7,Lookup!$A$2:$A$11,0)) | D7: BP006 | E7: =INDEX(Lookup!$E$2:$E$51,MATCH(D7,Lookup!$D$2:$D$51,0)) | F7: =INDEX(Lookup!$F$2:$F$51,MATCH(D7,Lookup!$D$2:$D$51,0)) | G7: 111 | H7: 25 | I7: 95 | J7: 2 | K7: 32 | L7: 5 | M7: 39 | N7: Healthy | O7: =G7+H7 | P7: =G7+H7-I7-J7 | Q7: =MAX(0,P7) | R7: =MAX(0,-P7) | S7: =IFERROR(J7/O7,0) | T7: =IFERROR(I7/O7,0) | U7: =IF(P7<=K7,"Reorder Required","Stock Sufficient") | V7: =IF(AND(Q7=M7,(U7="Reorder Required")=(N7="Reorder Required")),"OK","Mismatch")
A8: INV00007 | B8: OUT001 | C8: =INDEX(Lookup!$B$2:$B$11,MATCH(B8,Lookup!$A$2:$A$11,0)) | D8: BP007 | E8: =INDEX(Lookup!$E$2:$E$51,MATCH(D8,Lookup!$D$2:$D$51,0)) | F8: =INDEX(Lookup!$F$2:$F$51,MATCH(D8,Lookup!$D$2:$D$51,0)) | G8: 66 | H8: 29 | I8: 66 | J8: 2 | K8: 18 | L8: 4 | M8: 27 | N8: Healthy | O8: =G8+H8 | P8: =G8+H8-I8-J8 | Q8: =MAX(0,P8) | R8: =MAX(0,-P8) | S8: =IFERROR(J8/O8,0) | T8: =IFERROR(I8/O8,0) | U8: =IF(P8<=K8,"Reorder Required","Stock Sufficient") | V8: =IF(AND(Q8=M8,(U8="Reorder Required")=(N8="Reorder Required")),"OK","Mismatch")
A9: INV00008 | B9: OUT001 | C9: =INDEX(Lookup!$B$2:$B$11,MATCH(B9,Lookup!$A$2:$A$11,0)) | D9: BP008 | E9: =INDEX(Lookup!$E$2:$E$51,MATCH(D9,Lookup!$D$2:$D$51,0)) | F9: =INDEX(Lookup!$F$2:$F$51,MATCH(D9,Lookup!$D$2:$D$51,0)) | G9: 96 | H9: 74 | I9: 137 | J9: 1 | K9: 32 | L9: 4 | M9: 32 | N9: Reorder Required | O9: =G9+H9 | P9: =G9+H9-I9-J9 | Q9: =MAX(0,P9) | R9: =MAX(0,-P9) | S9: =IFERROR(J9/O9,0) | T9: =IFERROR(I9/O9,0) | U9: =IF(P9<=K9,"Reorder Required","Stock Sufficient") | V9: =IF(AND(Q9=M9,(U9="Reorder Required")=(N9="Reorder Required")),"OK","Mismatch") | W9: Restock immediately
A10: INV00009 | B10: OUT001 | C10: =INDEX(Lookup!$B$2:$B$11,MATCH(B10,Lookup!$A$2:$A$11,0)) | D10: BP009 | E10: =INDEX(Lookup!$E$2:$E$51,MATCH(D10,Lookup!$D$2:$D$51,0)) | F10: =INDEX(Lookup!$F$2:$F$51,MATCH(D10,Lookup!$D$2:$D$51,0)) | G10: 54 | H10: 84 | I10: 159 | J10: 1 | K10: 37 | L10: 3 | M10: 0 | N10: Reorder Required | O10: =G10+H10 | P10: =G10+H10-I10-J10 | Q10: =MAX(0,P10) | R10: =MAX(0,-P10) | S10: =IFERROR(J10/O10,0) | T10: =IFERROR(I10/O10,0) | U10: =IF(P10<=K10,"Reorder Required","Stock Sufficient") | V10: =IF(AND(Q10=M10,(U10="Reorder Required")=(N10="Reorder Required")),"OK","Mismatch") | W10: Restock immediately
A11: INV00010 | B11: OUT001 | C11: =INDEX(Lookup!$B$2:$B$11,MATCH(B11,Lookup!$A$2:$A$11,0)) | D11: BP010 | E11: =INDEX(Lookup!$E$2:$E$51,MATCH(D11,Lookup!$D$2:$D$51,0)) | F11: =INDEX(Lookup!$F$2:$F$51,MATCH(D11,Lookup!$D$2:$D$51,0)) | G11: 43 | H11: 86 | I11: 101 | J11: 2 | K11: 36 | L11: 3 | M11: 26 | N11: Reorder Required | O11: =G11+H11 | P11: =G11+H11-I11-J11 | Q11: =MAX(0,P11) | R11: =MAX(0,-P11) | S11: =IFERROR(J11/O11,0) | T11: =IFERROR(I11/O11,0) | U11: =IF(P11<=K11,"Reorder Required","Stock Sufficient") | V11: =IF(AND(Q11=M11,(U11="Reorder Required")=(N11="Reorder Required")),"OK","Mismatch") | W11: Restock immediately
A12: INV00011 | B12: OUT001 | C12: =INDEX(Lookup!$B$2:$B$11,MATCH(B12,Lookup!$A$2:$A$11,0)) | D12: BP011 | E12: =INDEX(Lookup!$E$2:$E$51,MATCH(D12,Lookup!$D$2:$D$51,0)) | F12: =INDEX(Lookup!$F$2:$F$51,MATCH(D12,Lookup!$D$2:$D$51,0)) | G12: 127 | H12: 45 | I12: 113 | J12: 1 | K12: 29 | L12: 2 | M12: 58 | N12: Healthy | O12: =G12+H12 | P12: =G12+H12-I12-J12 | Q12: =MAX(0,P12) | R12: =MAX(0,-P12) | S12: =IFERROR(J12/O12,0) | T12: =IFERROR(I12/O12,0) | U12: =IF(P12<=K12,"Reorder Required","Stock Sufficient") | V12: =IF(AND(Q12=M12,(U12="Reorder Required")=(N12="Reorder Required")),"OK","Mismatch")
A13: INV00012 | B13: OUT001 | C13: =INDEX(Lookup!$B$2:$B$11,MATCH(B13,Lookup!$A$2:$A$11,0)) | D13: BP012 | E13: =INDEX(Lookup!$E$2:$E$51,MATCH(D13,Lookup!$D$2:$D$51,0)) | F13: =INDEX(Lookup!$F$2:$F$51,MATCH(D13,Lookup!$D$2:$D$51,0)) | G13: 95 | H13: 53 | I13: 92 | J13: 2 | K13: 21 | L13: 5 | M13: 54 | N13: Healthy | O13: =G13+H13 | P13: =G13+H13-I13-J13 | Q13: =MAX(0,P13) | R13: =MAX(0,-P13) | S13: =IFERROR(J13/O13,0) | T13: =IFERROR(I13/O13,0) | U13: =IF(P13<=K13,"Reorder Required","Stock Sufficient") | V13: =IF(AND(Q13=M13,(U13="Reorder Required")=(N13="Reorder Required")),"OK","Mismatch")
A14: INV00013 | B14: OUT001 | C14: =INDEX(Lookup!$B$2:$B$11,MATCH(B14,Lookup!$A$2:$A$11,0)) | D14: BP013 | E14: =INDEX(Lookup!$E$2:$E$51,MATCH(D14,Lookup!$D$2:$D$51,0)) | F14: =INDEX(Lookup!$F$2:$F$51,MATCH(D14,Lookup!$D$2:$D$51,0)) | G14: 45 | H14: 38 | I14: 105 | J14: 0 | K14: 29 | L14: 1 | M14: 0 | N14: Reorder Required | O14: =G14+H14 | P14: =G14+H14-I14-J14 | Q14: =MAX(0,P14) | R14: =MAX(0,-P14) | S14: =IFERROR(J14/O14,0) | T14: =IFERROR(I14/O14,0) | U14: =IF(P14<=K14,"Reorder Required","Stock Sufficient") | V14: =IF(AND(Q14=M14,(U14="Reorder Required")=(N14="Reorder Required")),"OK","Mismatch") | W14: Restock immediately
A15: INV00014 | B15: OUT001 | C15: =INDEX(Lookup!$B$2:$B$11,MATCH(B15,Lookup!$A$2:$A$11,0)) | D15: BP014 | E15: =INDEX(Lookup!$E$2:$E$51,MATCH(D15,Lookup!$D$2:$D$51,0)) | F15: =INDEX(Lookup!$F$2:$F$51,MATCH(D15,Lookup!$D$2:$D$51,0)) | G15: 101 | H15: 75 | I15: 74 | J15: 0 | K15: 31 | L15: 3 | M15: 102 | N15: Healthy | O15: =G15+H15 | P15: =G15+H15-I15-J15 | Q15: =MAX(0,P15) | R15: =MAX(0,-P15) | S15: =IFERROR(J15/O15,0) | T15: =IFERROR(I15/O15,0) | U15: =IF(P15<=K15,"Reorder Required","Stock Sufficient") | V15: =IF(AND(Q15=M15,(U15="Reorder Required")=(N15="Reorder Required")),"OK","Mismatch")
A16: INV00015 | B16: OUT001 | C16: =INDEX(Lookup!$B$2:$B$11,MATCH(B16,Lookup!$A$2:$A$11,0)) | D16: BP015 | E16: =INDEX(Lookup!$E$2:$E$51,MATCH(D16,Lookup!$D$2:$D$51,0)) | F16: =INDEX(Lookup!$F$2:$F$51,MATCH(D16,Lookup!$D$2:$D$51,0)) | G16: 115 | H16: 25 | I16: 144 | J16: 2 | K16: 32 | L16: 3 | M16: 0 | N16: Reorder Required | O16: =G16+H16 | P16: =G16+H16-I16-J16 | Q16: =MAX(0,P16) | R16: =MAX(0,-P16) | S16: =IFERROR(J16/O16,0) | T16: =IFERROR(I16/O16,0) | U16: =IF(P16<=K16,"Reorder Required","Stock Sufficient") | V16: =IF(AND(Q16=M16,(U16="Reorder Required")=(N16="Reorder Required")),"OK","Mismatch") | W16: Restock immediately
A17: INV00016 | B17: OUT001 | C17: =INDEX(Lookup!$B$2:$B$11,MATCH(B17,Lookup!$A$2:$A$11,0)) | D17: BP016 | E17: =INDEX(Lookup!$E$2:$E$51,MATCH(D17,Lookup!$D$2:$D$51,0)) | F17: =INDEX(Lookup!$F$2:$F$51,MATCH(D17,Lookup!$D$2:$D$51,0)) | G17: 112 | H17: 75 | I17: 96 | J17: 1 | K17: 29 | L17: 1 | M17: 90 | N17: Healthy | O17: =G17+H17 | P17: =G17+H17-I17-J17 | Q17: =MAX(0,P17) | R17: =MAX(0,-P17) | S17: =IFERROR(J17/O17,0) | T17: =IFERROR(I17/O17,0) | U17: =IF(P17<=K17,"Reorder Required","Stock Sufficient") | V17: =IF(AND(Q17=M17,(U17="Reorder Required")=(N17="Reorder Required")),"OK","Mismatch")
A18: INV00017 | B18: OUT001 | C18: =INDEX(Lookup!$B$2:$B$11,MATCH(B18,Lookup!$A$2:$A$11,0)) | D18: BP017 | E18: =INDEX(Lookup!$E$2:$E$51,MATCH(D18,Lookup!$D$2:$D$51,0)) | F18: =INDEX(Lookup!$F$2:$F$51,MATCH(D18,Lookup!$D$2:$D$51,0)) | G18: 131 | H18: 43 | I18: 133 | J18: 0 | K18: 34 | L18: 5 | M18: 41 | N18: Healthy | O18: =G18+H18 | P18: =G18+H18-I18-J18 | Q18: =MAX(0,P18) | R18: =MAX(0,-P18) | S18: =IFERROR(J18/O18,0) | T18: =IFERROR(I18/O18,0) | U18: =IF(P18<=K18,"Reorder Required","Stock Sufficient") | V18: =IF(AND(Q18=M18,(U18="Reorder Required")=(N18="Reorder Required")),"OK","Mismatch")
A19: INV00018 | B19: OUT001 | C19: =INDEX(Lookup!$B$2:$B$11,MATCH(B19,Lookup!$A$2:$A$11,0)) | D19: BP018 | E19: =INDEX(Lookup!$E$2:$E$51,MATCH(D19,Lookup!$D$2:$D$51,0)) | F19: =INDEX(Lookup!$F$2:$F$51,MATCH(D19,Lookup!$D$2:$D$51,0)) | G19: 51 | H19: 53 | I19: 114 | J19: 0 | K19: 23 | L19: 1 | M19: 0 | N19: Reorder Required | O19: =G19+H19 | P19: =G19+H19-I19-J19 | Q19: =MAX(0,P19) | R19: =MAX(0,-P19) | S19: =IFERROR(J19/O19,0) | T19: =IFERROR(I19/O19,0) | U19: =IF(P19<=K19,"Reorder Required","Stock Sufficient") | V19: =IF(AND(Q19=M19,(U19="Reorder Required")=(N19="Reorder Required")),"OK","Mismatch") | W19: Restock immediately
A20: INV00019 | B20: OUT001 | C20: =INDEX(Lookup!$B$2:$B$11,MATCH(B20,Lookup!$A$2:$A$11,0)) | D20: BP019 | E20: =INDEX(Lookup!$E$2:$E$51,MATCH(D20,Lookup!$D$2:$D$51,0)) | F20: =INDEX(Lookup!$F$2:$F$51,MATCH(D20,Lookup!$D$2:$D$51,0)) | G20: 92 | H20: 36 | I20: 89 | J20: 1 | K20: 28 | L20: 2 | M20: 38 | N20: Healthy | O20: =G20+H20 | P20: =G20+H20-I20-J20 | Q20: =MAX(0,P20) | R20: =MAX(0,-P20) | S20: =IFERROR(J20/O20,0) | T20: =IFERROR(I20/O20,0) | U20: =IF(P20<=K20,"Reorder Required","Stock Sufficient") | V20: =IF(AND(Q20=M20,(U20="Reorder Required")=(N20="Reorder Required")),"OK","Mismatch")
A21: INV00020 | B21: OUT001 | C21: =INDEX(Lookup!$B$2:$B$11,MATCH(B21,Lookup!$A$2:$A$11,0)) | D21: BP020 | E21: =INDEX(Lookup!$E$2:$E$51,MATCH(D21,Lookup!$D$2:$D$51,0)) | F21: =INDEX(Lookup!$F$2:$F$51,MATCH(D21,Lookup!$D$2:$D$51,0)) | G21: 72 | H21: 80 | I21: 146 | J21: 1 | K21: 28 | L21: 1 | M21: 5 | N21: Reorder Required | O21: =G21+H21 | P21: =G21+H21-I21-J21 | Q21: =MAX(0,P21) | R21: =MAX(0,-P21) | S21: =IFERROR(J21/O21,0) | T21: =IFERROR(I21/O21,0) | U21: =IF(P21<=K21,"Reorder Required","Stock Sufficient") | V21: =IF(AND(Q21=M21,(U21="Reorder Required")=(N21="Reorder Required")),"OK","Mismatch") | W21: Restock immediately
A22: INV00021 | B22: OUT001 | C22: =INDEX(Lookup!$B$2:$B$11,MATCH(B22,Lookup!$A$2:$A$11,0)) | D22: BP021 | E22: =INDEX(Lookup!$E$2:$E$51,MATCH(D22,Lookup!$D$2:$D$51,0)) | F22: =INDEX(Lookup!$F$2:$F$51,MATCH(D22,Lookup!$D$2:$D$51,0)) | G22: 52 | H22: 31 | I22: 77 | J22: 3 | K22: 19 | L22: 5 | M22: 3 | N22: Reorder Required | O22: =G22+H22 | P22: =G22+H22-I22-J22 | Q22: =MAX(0,P22) | R22: =MAX(0,-P22) | S22: =IFERROR(J22/O22,0) | T22: =IFERROR(I22/O22,0) | U22: =IF(P22<=K22,"Reorder Required","Stock Sufficient") | V22: =IF(AND(Q22=M22,(U22="Reorder Required")=(N22="Reorder Required")),"OK","Mismatch") | W22: Restock immediately
A23: INV00022 | B23: OUT001 | C23: =INDEX(Lookup!$B$2:$B$11,MATCH(B23,Lookup!$A$2:$A$11,0)) | D23: BP022 | E23: =INDEX(Lookup!$E$2:$E$51,MATCH(D23,Lookup!$D$2:$D$51,0)) | F23: =INDEX(Lookup!$F$2:$F$51,MATCH(D23,Lookup!$D$2:$D$51,0)) | G23: 141 | H23: 94 | I23: 115 | J23: 0 | K23: 29 | L23: 5 | M23: 120 | N23: Healthy | O23: =G23+H23 | P23: =G23+H23-I23-J23 | Q23: =MAX(0,P23) | R23: =MAX(0,-P23) | S23: =IFERROR(J23/O23,0) | T23: =IFERROR(I23/O23,0) | U23: =IF(P23<=K23,"Reorder Required","Stock Sufficient") | V23: =IF(AND(Q23=M23,(U23="Reorder Required")=(N23="Reorder Required")),"OK","Mismatch")
A24: INV00023 | B24: OUT001 | C24: =INDEX(Lookup!$B$2:$B$11,MATCH(B24,Lookup!$A$2:$A$11,0)) | D24: BP023 | E24: =INDEX(Lookup!$E$2:$E$51,MATCH(D24,Lookup!$D$2:$D$51,0)) | F24: =INDEX(Lookup!$F$2:$F$51,MATCH(D24,Lookup!$D$2:$D$51,0)) | G24: 55 | H24: 92 | I24: 119 | J24: 3 | K24: 30 | L24: 5 | M24: 25 | N24: Reorder Required | O24: =G24+H24 | P24: =G24+H24-I24-J24 | Q24: =MAX(0,P24) | R24: =MAX(0,-P24) | S24: =IFERROR(J24/O24,0) | T24: =IFERROR(I24/O24,0) | U24: =IF(P24<=K24,"Reorder Required","Stock Sufficient") | V24: =IF(AND(Q24=M24,(U24="Reorder Required")=(N24="Reorder Required")),"OK","Mismatch") | W24: Restock immediately
A25: INV00024 | B25: OUT001 | C25: =INDEX(Lookup!$B$2:$B$11,MATCH(B25,Lookup!$A$2:$A$11,0)) | D25: BP024 | E25: =INDEX(Lookup!$E$2:$E$51,MATCH(D25,Lookup!$D$2:$D$51,0)) | F25: =INDEX(Lookup!$F$2:$F$51,MATCH(D25,Lookup!$D$2:$D$51,0)) | G25: 150 | H25: 69 | I25: 86 | J25: 3 | K25: 28 | L25: 3 | M25: 130 | N25: Healthy | O25: =G25+H25 | P25: =G25+H25-I25-J25 | Q25: =MAX(0,P25) | R25: =MAX(0,-P25) | S25: =IFERROR(J25/O25,0) | T25: =IFERROR(I25/O25,0) | U25: =IF(P25<=K25,"Reorder Required","Stock Sufficient") | V25: =IF(AND(Q25=M25,(U25="Reorder Required")=(N25="Reorder Required")),"OK","Mismatch")
A26: INV00025 | B26: OUT001 | C26: =INDEX(Lookup!$B$2:$B$11,MATCH(B26,Lookup!$A$2:$A$11,0)) | D26: BP025 | E26: =INDEX(Lookup!$E$2:$E$51,MATCH(D26,Lookup!$D$2:$D$51,0)) | F26: =INDEX(Lookup!$F$2:$F$51,MATCH(D26,Lookup!$D$2:$D$51,0)) | G26: 86 | H26: 30 | I26: 117 | J26: 2 | K26: 26 | L26: 5 | M26: 0 | N26: Reorder Required | O26: =G26+H26 | P26: =G26+H26-I26-J26 | Q26: =MAX(0,P26) | R26: =MAX(0,-P26) | S26: =IFERROR(J26/O26,0) | T26: =IFERROR(I26/O26,0) | U26: =IF(P26<=K26,"Reorder Required","Stock Sufficient") | V26: =IF(AND(Q26=M26,(U26="Reorder Required")=(N26="Reorder Required")),"OK","Mismatch") | W26: Restock immediately
A27: INV00026 | B27: OUT001 | C27: =INDEX(Lookup!$B$2:$B$11,MATCH(B27,Lookup!$A$2:$A$11,0)) | D27: BP026 | E27: =INDEX(Lookup!$E$2:$E$51,MATCH(D27,Lookup!$D$2:$D$51,0)) | F27: =INDEX(Lookup!$F$2:$F$51,MATCH(D27,Lookup!$D$2:$D$51,0)) | G27: 53 | H27: 25 | I27: 114 | J27: 2 | K27: 40 | L27: 5 | M27: 0 | N27: Reorder Required | O27: =G27+H27 | P27: =G27+H27-I27-J27 | Q27: =MAX(0,P27) | R27: =MAX(0,-P27) | S27: =IFERROR(J27/O27,0) | T27: =IFERROR(I27/O27,0) | U27: =IF(P27<=K27,"Reorder Required","Stock Sufficient") | V27: =IF(AND(Q27=M27,(U27="Reorder Required")=(N27="Reorder Required")),"OK","Mismatch") | W27: Restock immediately
A28: INV00027 | B28: OUT001 | C28: =INDEX(Lookup!$B$2:$B$11,MATCH(B28,Lookup!$A$2:$A$11,0)) | D28: BP027 | E28: =INDEX(Lookup!$E$2:$E$51,MATCH(D28,Lookup!$D$2:$D$51,0)) | F28: =INDEX(Lookup!$F$2:$F$51,MATCH(D28,Lookup!$D$2:$D$51,0)) | G28: 44 | H28: 39 | I28: 134 | J28: 0 | K28: 37 | L28: 4 | M28: 0 | N28: Reorder Required | O28: =G28+H28 | P28: =G28+H28-I28-J28 | Q28: =MAX(0,P28) | R28: =MAX(0,-P28) | S28: =IFERROR(J28/O28,0) | T28: =IFERROR(I28/O28,0) | U28: =IF(P28<=K28,"Reorder Required","Stock Sufficient") | V28: =IF(AND(Q28=M28,(U28="Reorder Required")=(N28="Reorder Required")),"OK","Mismatch") | W28: Restock immediately
A29: INV00028 | B29: OUT001 | C29: =INDEX(Lookup!$B$2:$B$11,MATCH(B29,Lookup!$A$2:$A$11,0)) | D29: BP028 | E29: =INDEX(Lookup!$E$2:$E$51,MATCH(D29,Lookup!$D$2:$D$51,0)) | F29: =INDEX(Lookup!$F$2:$F$51,MATCH(D29,Lookup!$D$2:$D$51,0)) | G29: 41 | H29: 44 | I29: 99 | J29: 0 | K29: 17 | L29: 5 | M29: 0 | N29: Reorder Required | O29: =G29+H29 | P29: =G29+H29-I29-J29 | Q29: =MAX(0,P29) | R29: =MAX(0,-P29) | S29: =IFERROR(J29/O29,0) | T29: =IFERROR(I29/O29,0) | U29: =IF(P29<=K29,"Reorder Required","Stock Sufficient") | V29: =IF(AND(Q29=M29,(U29="Reorder Required")=(N29="Reorder Required")),"OK","Mismatch") | W29: Restock immediately
A30: INV00029 | B30: OUT001 | C30: =INDEX(Lookup!$B$2:$B$11,MATCH(B30,Lookup!$A$2:$A$11,0)) | D30: BP029 | E30: =INDEX(Lookup!$E$2:$E$51,MATCH(D30,Lookup!$D$2:$D$51,0)) | F30: =INDEX(Lookup!$F$2:$F$51,MATCH(D30,Lookup!$D$2:$D$51,0)) | G30: 114 | H30: 24 | I30: 173 | J30: 1 | K30: 15 | L30: 2 | M30: 0 | N30: Reorder Required | O30: =G30+H30 | P30: =G30+H30-I30-J30 | Q30: =MAX(0,P30) | R30: =MAX(0,-P30) | S30: =IFERROR(J30/O30,0) | T30: =IFERROR(I30/O30,0) | U30: =IF(P30<=K30,"Reorder Required","Stock Sufficient") | V30: =IF(AND(Q30=M30,(U30="Reorder Required")=(N30="Reorder Required")),"OK","Mismatch") | W30: Restock immediately
A31: INV00030 | B31: OUT001 | C31: =INDEX(Lookup!$B$2:$B$11,MATCH(B31,Lookup!$A$2:$A$11,0)) | D31: BP030 | E31: =INDEX(Lookup!$E$2:$E$51,MATCH(D31,Lookup!$D$2:$D$51,0)) | F31: =INDEX(Lookup!$F$2:$F$51,MATCH(D31,Lookup!$D$2:$D$51,0)) | G31: 53 | H31: 100 | I31: 90 | J31: 4 | K31: 16 | L31: 1 | M31: 59 | N31: Healthy | O31: =G31+H31 | P31: =G31+H31-I31-J31 | Q31: =MAX(0,P31) | R31: =MAX(0,-P31) | S31: =IFERROR(J31/O31,0) | T31: =IFERROR(I31/O31,0) | U31: =IF(P31<=K31,"Reorder Required","Stock Sufficient") | V31: =IF(AND(Q31=M31,(U31="Reorder Required")=(N31="Reorder Required")),"OK","Mismatch")
A32: INV00031 | B32: OUT001 | C32: =INDEX(Lookup!$B$2:$B$11,MATCH(B32,Lookup!$A$2:$A$11,0)) | D32: BP031 | E32: =INDEX(Lookup!$E$2:$E$51,MATCH(D32,Lookup!$D$2:$D$51,0)) | F32: =INDEX(Lookup!$F$2:$F$51,MATCH(D32,Lookup!$D$2:$D$51,0)) | G32: 120 | H32: 82 | I32: 114 | J32: 7 | K32: 30 | L32: 2 | M32: 81 | N32: Healthy | O32: =G32+H32 | P32: =G32+H32-I32-J32 | Q32: =MAX(0,P32) | R32: =MAX(0,-P32) | S32: =IFERROR(J32/O32,0) | T32: =IFERROR(I32/O32,0) | U32: =IF(P32<=K32,"Reorder Required","Stock Sufficient") | V32: =IF(AND(Q32=M32,(U32="Reorder Required")=(N32="Reorder Required")),"OK","Mismatch")
A33: INV00032 | B33: OUT001 | C33: =INDEX(Lookup!$B$2:$B$11,MATCH(B33,Lookup!$A$2:$A$11,0)) | D33: BP032 | E33: =INDEX(Lookup!$E$2:$E$51,MATCH(D33,Lookup!$D$2:$D$51,0)) | F33: =INDEX(Lookup!$F$2:$F$51,MATCH(D33,Lookup!$D$2:$D$51,0)) | G33: 40 | H33: 20 | I33: 158 | J33: 5 | K33: 38 | L33: 1 | M33: 0 | N33: Reorder Required | O33: =G33+H33 | P33: =G33+H33-I33-J33 | Q33: =MAX(0,P33) | R33: =MAX(0,-P33) | S33: =IFERROR(J33/O33,0) | T33: =IFERROR(I33/O33,0) | U33: =IF(P33<=K33,"Reorder Required","Stock Sufficient") | V33: =IF(AND(Q33=M33,(U33="Reorder Required")=(N33="Reorder Required")),"OK","Mismatch") | W33: Restock immediately
A34: INV00033 | B34: OUT001 | C34: =INDEX(Lookup!$B$2:$B$11,MATCH(B34,Lookup!$A$2:$A$11,0)) | D34: BP033 | E34: =INDEX(Lookup!$E$2:$E$51,MATCH(D34,Lookup!$D$2:$D$51,0)) | F34: =INDEX(Lookup!$F$2:$F$51,MATCH(D34,Lookup!$D$2:$D$51,0)) | G34: 98 | H34: 46 | I34: 88 | J34: 5 | K34: 40 | L34: 5 | M34: 51 | N34: Healthy | O34: =G34+H34 | P34: =G34+H34-I34-J34 | Q34: =MAX(0,P34) | R34: =MAX(0,-P34) | S34: =IFERROR(J34/O34,0) | T34: =IFERROR(I34/O34,0) | U34: =IF(P34<=K34,"Reorder Required","Stock Sufficient") | V34: =IF(AND(Q34=M34,(U34="Reorder Required")=(N34="Reorder Required")),"OK","Mismatch")
A35: INV00034 | B35: OUT001 | C35: =INDEX(Lookup!$B$2:$B$11,MATCH(B35,Lookup!$A$2:$A$11,0)) | D35: BP034 | E35: =INDEX(Lookup!$E$2:$E$51,MATCH(D35,Lookup!$D$2:$D$51,0)) | F35: =INDEX(Lookup!$F$2:$F$51,MATCH(D35,Lookup!$D$2:$D$51,0)) | G35: 90 | H35: 22 | I35: 93 | J35: 3 | K35: 32 | L35: 4 | M35: 16 | N35: Reorder Required | O35: =G35+H35 | P35: =G35+H35-I35-J35 | Q35: =MAX(0,P35) | R35: =MAX(0,-P35) | S35: =IFERROR(J35/O35,0) | T35: =IFERROR(I35/O35,0) | U35: =IF(P35<=K35,"Reorder Required","Stock Sufficient") | V35: =IF(AND(Q35=M35,(U35="Reorder Required")=(N35="Reorder Required")),"OK","Mismatch") | W35: Restock immediately
A36: INV00035 | B36: OUT001 | C36: =INDEX(Lookup!$B$2:$B$11,MATCH(B36,Lookup!$A$2:$A$11,0)) | D36: BP035 | E36: =INDEX(Lookup!$E$2:$E$51,MATCH(D36,Lookup!$D$2:$D$51,0)) | F36: =INDEX(Lookup!$F$2:$F$51,MATCH(D36,Lookup!$D$2:$D$51,0)) | G36: 132 | H36: 53 | I36: 70 | J36: 7 | K36: 29 | L36: 5 | M36: 108 | N36: Healthy | O36: =G36+H36 | P36: =G36+H36-I36-J36 | Q36: =MAX(0,P36) | R36: =MAX(0,-P36) | S36: =IFERROR(J36/O36,0) | T36: =IFERROR(I36/O36,0) | U36: =IF(P36<=K36,"Reorder Required","Stock Sufficient") | V36: =IF(AND(Q36=M36,(U36="Reorder Required")=(N36="Reorder Required")),"OK","Mismatch")
